{
 "cells": [
  {
   "cell_type": "code",
   "execution_count": null,
   "metadata": {},
   "outputs": [
    {
     "name": "stderr",
     "output_type": "stream",
     "text": [
      "2023-01-10 04:05:54.431475: I tensorflow/core/platform/cpu_feature_guard.cc:193] This TensorFlow binary is optimized with oneAPI Deep Neural Network Library (oneDNN) to use the following CPU instructions in performance-critical operations:  AVX2 AVX512F FMA\n",
      "To enable them in other operations, rebuild TensorFlow with the appropriate compiler flags.\n",
      "2023-01-10 04:05:58.689443: W tensorflow/compiler/xla/stream_executor/platform/default/dso_loader.cc:64] Could not load dynamic library 'libcudart.so.11.0'; dlerror: libcudart.so.11.0: cannot open shared object file: No such file or directory\n",
      "2023-01-10 04:05:58.689473: I tensorflow/compiler/xla/stream_executor/cuda/cudart_stub.cc:29] Ignore above cudart dlerror if you do not have a GPU set up on your machine.\n",
      "2023-01-10 04:06:09.558312: W tensorflow/compiler/xla/stream_executor/platform/default/dso_loader.cc:64] Could not load dynamic library 'libnvinfer.so.7'; dlerror: libnvinfer.so.7: cannot open shared object file: No such file or directory\n",
      "2023-01-10 04:06:09.558743: W tensorflow/compiler/xla/stream_executor/platform/default/dso_loader.cc:64] Could not load dynamic library 'libnvinfer_plugin.so.7'; dlerror: libnvinfer_plugin.so.7: cannot open shared object file: No such file or directory\n",
      "2023-01-10 04:06:09.558779: W tensorflow/compiler/tf2tensorrt/utils/py_utils.cc:38] TF-TRT Warning: Cannot dlopen some TensorRT libraries. If you would like to use Nvidia GPU with TensorRT, please make sure the missing libraries mentioned above are installed properly.\n"
     ]
    }
   ],
   "source": [
    "import tensorflow as tf\n",
    "import numpy as np\n",
    "import matplotlib.pyplot as plt\n",
    "from keras.preprocessing.image import ImageDataGenerator"
   ]
  },
  {
   "cell_type": "code",
   "execution_count": null,
   "metadata": {},
   "outputs": [],
   "source": [
    "train_datagen = ImageDataGenerator(rescale=1./255)\n",
    "# test_datagen = ImageDataGenerator(rescale=1./255)"
   ]
  },
  {
   "cell_type": "code",
   "execution_count": null,
   "metadata": {},
   "outputs": [
    {
     "name": "stdout",
     "output_type": "stream",
     "text": [
      "Found 983 images belonging to 20 classes.\n"
     ]
    }
   ],
   "source": [
    "train_generator = train_datagen.flow_from_directory('./dataset',target_size=(64,64),batch_size=32,class_mode='categorical')\n",
    "# test_generator = test_datagen.flow_from_directory()"
   ]
  },
  {
   "cell_type": "code",
   "execution_count": null,
   "metadata": {},
   "outputs": [
    {
     "name": "stderr",
     "output_type": "stream",
     "text": [
      "2022-12-27 10:50:11.348826: W tensorflow/compiler/xla/stream_executor/platform/default/dso_loader.cc:64] Could not load dynamic library 'libcuda.so.1'; dlerror: libcuda.so.1: cannot open shared object file: No such file or directory\n",
      "2022-12-27 10:50:11.349065: W tensorflow/compiler/xla/stream_executor/cuda/cuda_driver.cc:265] failed call to cuInit: UNKNOWN ERROR (303)\n",
      "2022-12-27 10:50:11.349106: I tensorflow/compiler/xla/stream_executor/cuda/cuda_diagnostics.cc:156] kernel driver does not appear to be running on this host (codespaces-01f5e0): /proc/driver/nvidia/version does not exist\n",
      "2022-12-27 10:50:11.401168: I tensorflow/core/platform/cpu_feature_guard.cc:193] This TensorFlow binary is optimized with oneAPI Deep Neural Network Library (oneDNN) to use the following CPU instructions in performance-critical operations:  AVX2 AVX512F FMA\n",
      "To enable them in other operations, rebuild TensorFlow with the appropriate compiler flags.\n"
     ]
    }
   ],
   "source": [
    "resnet_50_model = tf.keras.applications.mobilenet_v2.MobileNetV2(\n",
    "    input_shape=(64,64,3),\n",
    "    include_top=False,\n",
    "    weights='imagenet'\n",
    ")\n",
    "resnet_50_model.trainable = False"
   ]
  },
  {
   "cell_type": "code",
   "execution_count": null,
   "metadata": {},
   "outputs": [],
   "source": [
    "model = tf.keras.Sequential([\n",
    "    resnet_50_model,\n",
    "    tf.keras.layers.Dense(4, activation='softmax')\n",
    "])"
   ]
  },
  {
   "cell_type": "code",
   "execution_count": null,
   "metadata": {},
   "outputs": [],
   "source": [
    "model.compile(optimizer='adam', loss='categorical_crossentropy', metrics=['accuracy'])"
   ]
  },
  {
   "cell_type": "code",
   "execution_count": null,
   "metadata": {},
   "outputs": [
    {
     "name": "stdout",
     "output_type": "stream",
     "text": [
      "Model: \"sequential\"\n",
      "_________________________________________________________________\n",
      " Layer (type)                Output Shape              Param #   \n",
      "=================================================================\n",
      " resnet50 (Functional)       (None, None, None, 2048)  23587712  \n",
      "                                                                 \n",
      " global_average_pooling2d (G  (None, 2048)             0         \n",
      " lobalAveragePooling2D)                                          \n",
      "                                                                 \n",
      " dense (Dense)               (None, 4)                 8196      \n",
      "                                                                 \n",
      "=================================================================\n",
      "Total params: 23,595,908\n",
      "Trainable params: 8,196\n",
      "Non-trainable params: 23,587,712\n",
      "_________________________________________________________________\n"
     ]
    }
   ],
   "source": [
    "model.summary()"
   ]
  },
  {
   "cell_type": "code",
   "execution_count": null,
   "metadata": {},
   "outputs": [
    {
     "ename": "InvalidArgumentError",
     "evalue": "Graph execution error:\n\nDetected at node 'categorical_crossentropy/softmax_cross_entropy_with_logits' defined at (most recent call last):\n    File \"/home/codespace/.python/current/lib/python3.10/runpy.py\", line 196, in _run_module_as_main\n      return _run_code(code, main_globals, None,\n    File \"/home/codespace/.python/current/lib/python3.10/runpy.py\", line 86, in _run_code\n      exec(code, run_globals)\n    File \"/home/codespace/.local/lib/python3.10/site-packages/ipykernel_launcher.py\", line 17, in <module>\n      app.launch_new_instance()\n    File \"/home/codespace/.local/lib/python3.10/site-packages/traitlets/config/application.py\", line 985, in launch_instance\n      app.start()\n    File \"/home/codespace/.local/lib/python3.10/site-packages/ipykernel/kernelapp.py\", line 712, in start\n      self.io_loop.start()\n    File \"/home/codespace/.local/lib/python3.10/site-packages/tornado/platform/asyncio.py\", line 215, in start\n      self.asyncio_loop.run_forever()\n    File \"/home/codespace/.python/current/lib/python3.10/asyncio/base_events.py\", line 600, in run_forever\n      self._run_once()\n    File \"/home/codespace/.python/current/lib/python3.10/asyncio/base_events.py\", line 1896, in _run_once\n      handle._run()\n    File \"/home/codespace/.python/current/lib/python3.10/asyncio/events.py\", line 80, in _run\n      self._context.run(self._callback, *self._args)\n    File \"/home/codespace/.local/lib/python3.10/site-packages/ipykernel/kernelbase.py\", line 510, in dispatch_queue\n      await self.process_one()\n    File \"/home/codespace/.local/lib/python3.10/site-packages/ipykernel/kernelbase.py\", line 499, in process_one\n      await dispatch(*args)\n    File \"/home/codespace/.local/lib/python3.10/site-packages/ipykernel/kernelbase.py\", line 406, in dispatch_shell\n      await result\n    File \"/home/codespace/.local/lib/python3.10/site-packages/ipykernel/kernelbase.py\", line 730, in execute_request\n      reply_content = await reply_content\n    File \"/home/codespace/.local/lib/python3.10/site-packages/ipykernel/ipkernel.py\", line 383, in do_execute\n      res = shell.run_cell(\n    File \"/home/codespace/.local/lib/python3.10/site-packages/ipykernel/zmqshell.py\", line 528, in run_cell\n      return super().run_cell(*args, **kwargs)\n    File \"/home/codespace/.local/lib/python3.10/site-packages/IPython/core/interactiveshell.py\", line 2940, in run_cell\n      result = self._run_cell(\n    File \"/home/codespace/.local/lib/python3.10/site-packages/IPython/core/interactiveshell.py\", line 2995, in _run_cell\n      return runner(coro)\n    File \"/home/codespace/.local/lib/python3.10/site-packages/IPython/core/async_helpers.py\", line 129, in _pseudo_sync_runner\n      coro.send(None)\n    File \"/home/codespace/.local/lib/python3.10/site-packages/IPython/core/interactiveshell.py\", line 3194, in run_cell_async\n      has_raised = await self.run_ast_nodes(code_ast.body, cell_name,\n    File \"/home/codespace/.local/lib/python3.10/site-packages/IPython/core/interactiveshell.py\", line 3373, in run_ast_nodes\n      if await self.run_code(code, result, async_=asy):\n    File \"/home/codespace/.local/lib/python3.10/site-packages/IPython/core/interactiveshell.py\", line 3433, in run_code\n      exec(code_obj, self.user_global_ns, self.user_ns)\n    File \"/tmp/ipykernel_8918/4292263780.py\", line 1, in <module>\n      history = model.fit(train_generator, epochs=1, validation_data=0.2)\n    File \"/home/codespace/.python/current/lib/python3.10/site-packages/keras/utils/traceback_utils.py\", line 65, in error_handler\n      return fn(*args, **kwargs)\n    File \"/home/codespace/.python/current/lib/python3.10/site-packages/keras/engine/training.py\", line 1650, in fit\n      tmp_logs = self.train_function(iterator)\n    File \"/home/codespace/.python/current/lib/python3.10/site-packages/keras/engine/training.py\", line 1249, in train_function\n      return step_function(self, iterator)\n    File \"/home/codespace/.python/current/lib/python3.10/site-packages/keras/engine/training.py\", line 1233, in step_function\n      outputs = model.distribute_strategy.run(run_step, args=(data,))\n    File \"/home/codespace/.python/current/lib/python3.10/site-packages/keras/engine/training.py\", line 1222, in run_step\n      outputs = model.train_step(data)\n    File \"/home/codespace/.python/current/lib/python3.10/site-packages/keras/engine/training.py\", line 1024, in train_step\n      loss = self.compute_loss(x, y, y_pred, sample_weight)\n    File \"/home/codespace/.python/current/lib/python3.10/site-packages/keras/engine/training.py\", line 1082, in compute_loss\n      return self.compiled_loss(\n    File \"/home/codespace/.python/current/lib/python3.10/site-packages/keras/engine/compile_utils.py\", line 265, in __call__\n      loss_value = loss_obj(y_t, y_p, sample_weight=sw)\n    File \"/home/codespace/.python/current/lib/python3.10/site-packages/keras/losses.py\", line 152, in __call__\n      losses = call_fn(y_true, y_pred)\n    File \"/home/codespace/.python/current/lib/python3.10/site-packages/keras/losses.py\", line 284, in call\n      return ag_fn(y_true, y_pred, **self._fn_kwargs)\n    File \"/home/codespace/.python/current/lib/python3.10/site-packages/keras/losses.py\", line 2004, in categorical_crossentropy\n      return backend.categorical_crossentropy(\n    File \"/home/codespace/.python/current/lib/python3.10/site-packages/keras/backend.py\", line 5538, in categorical_crossentropy\n      return tf.nn.softmax_cross_entropy_with_logits(\nNode: 'categorical_crossentropy/softmax_cross_entropy_with_logits'\nlogits and labels must be broadcastable: logits_size=[32,4] labels_size=[32,20]\n\t [[{{node categorical_crossentropy/softmax_cross_entropy_with_logits}}]] [Op:__inference_train_function_19998]",
     "output_type": "error",
     "traceback": [
      "\u001b[0;31m---------------------------------------------------------------------------\u001b[0m",
      "\u001b[0;31mInvalidArgumentError\u001b[0m                      Traceback (most recent call last)",
      "Cell \u001b[0;32mIn[20], line 1\u001b[0m\n\u001b[0;32m----> 1\u001b[0m history \u001b[39m=\u001b[39m model\u001b[39m.\u001b[39;49mfit(train_generator, epochs\u001b[39m=\u001b[39;49m\u001b[39m1\u001b[39;49m, validation_data\u001b[39m=\u001b[39;49m\u001b[39m0.2\u001b[39;49m)\n",
      "File \u001b[0;32m~/.python/current/lib/python3.10/site-packages/keras/utils/traceback_utils.py:70\u001b[0m, in \u001b[0;36mfilter_traceback.<locals>.error_handler\u001b[0;34m(*args, **kwargs)\u001b[0m\n\u001b[1;32m     67\u001b[0m     filtered_tb \u001b[39m=\u001b[39m _process_traceback_frames(e\u001b[39m.\u001b[39m__traceback__)\n\u001b[1;32m     68\u001b[0m     \u001b[39m# To get the full stack trace, call:\u001b[39;00m\n\u001b[1;32m     69\u001b[0m     \u001b[39m# `tf.debugging.disable_traceback_filtering()`\u001b[39;00m\n\u001b[0;32m---> 70\u001b[0m     \u001b[39mraise\u001b[39;00m e\u001b[39m.\u001b[39mwith_traceback(filtered_tb) \u001b[39mfrom\u001b[39;00m \u001b[39mNone\u001b[39m\n\u001b[1;32m     71\u001b[0m \u001b[39mfinally\u001b[39;00m:\n\u001b[1;32m     72\u001b[0m     \u001b[39mdel\u001b[39;00m filtered_tb\n",
      "File \u001b[0;32m~/.python/current/lib/python3.10/site-packages/tensorflow/python/eager/execute.py:52\u001b[0m, in \u001b[0;36mquick_execute\u001b[0;34m(op_name, num_outputs, inputs, attrs, ctx, name)\u001b[0m\n\u001b[1;32m     50\u001b[0m \u001b[39mtry\u001b[39;00m:\n\u001b[1;32m     51\u001b[0m   ctx\u001b[39m.\u001b[39mensure_initialized()\n\u001b[0;32m---> 52\u001b[0m   tensors \u001b[39m=\u001b[39m pywrap_tfe\u001b[39m.\u001b[39mTFE_Py_Execute(ctx\u001b[39m.\u001b[39m_handle, device_name, op_name,\n\u001b[1;32m     53\u001b[0m                                       inputs, attrs, num_outputs)\n\u001b[1;32m     54\u001b[0m \u001b[39mexcept\u001b[39;00m core\u001b[39m.\u001b[39m_NotOkStatusException \u001b[39mas\u001b[39;00m e:\n\u001b[1;32m     55\u001b[0m   \u001b[39mif\u001b[39;00m name \u001b[39mis\u001b[39;00m \u001b[39mnot\u001b[39;00m \u001b[39mNone\u001b[39;00m:\n",
      "\u001b[0;31mInvalidArgumentError\u001b[0m: Graph execution error:\n\nDetected at node 'categorical_crossentropy/softmax_cross_entropy_with_logits' defined at (most recent call last):\n    File \"/home/codespace/.python/current/lib/python3.10/runpy.py\", line 196, in _run_module_as_main\n      return _run_code(code, main_globals, None,\n    File \"/home/codespace/.python/current/lib/python3.10/runpy.py\", line 86, in _run_code\n      exec(code, run_globals)\n    File \"/home/codespace/.local/lib/python3.10/site-packages/ipykernel_launcher.py\", line 17, in <module>\n      app.launch_new_instance()\n    File \"/home/codespace/.local/lib/python3.10/site-packages/traitlets/config/application.py\", line 985, in launch_instance\n      app.start()\n    File \"/home/codespace/.local/lib/python3.10/site-packages/ipykernel/kernelapp.py\", line 712, in start\n      self.io_loop.start()\n    File \"/home/codespace/.local/lib/python3.10/site-packages/tornado/platform/asyncio.py\", line 215, in start\n      self.asyncio_loop.run_forever()\n    File \"/home/codespace/.python/current/lib/python3.10/asyncio/base_events.py\", line 600, in run_forever\n      self._run_once()\n    File \"/home/codespace/.python/current/lib/python3.10/asyncio/base_events.py\", line 1896, in _run_once\n      handle._run()\n    File \"/home/codespace/.python/current/lib/python3.10/asyncio/events.py\", line 80, in _run\n      self._context.run(self._callback, *self._args)\n    File \"/home/codespace/.local/lib/python3.10/site-packages/ipykernel/kernelbase.py\", line 510, in dispatch_queue\n      await self.process_one()\n    File \"/home/codespace/.local/lib/python3.10/site-packages/ipykernel/kernelbase.py\", line 499, in process_one\n      await dispatch(*args)\n    File \"/home/codespace/.local/lib/python3.10/site-packages/ipykernel/kernelbase.py\", line 406, in dispatch_shell\n      await result\n    File \"/home/codespace/.local/lib/python3.10/site-packages/ipykernel/kernelbase.py\", line 730, in execute_request\n      reply_content = await reply_content\n    File \"/home/codespace/.local/lib/python3.10/site-packages/ipykernel/ipkernel.py\", line 383, in do_execute\n      res = shell.run_cell(\n    File \"/home/codespace/.local/lib/python3.10/site-packages/ipykernel/zmqshell.py\", line 528, in run_cell\n      return super().run_cell(*args, **kwargs)\n    File \"/home/codespace/.local/lib/python3.10/site-packages/IPython/core/interactiveshell.py\", line 2940, in run_cell\n      result = self._run_cell(\n    File \"/home/codespace/.local/lib/python3.10/site-packages/IPython/core/interactiveshell.py\", line 2995, in _run_cell\n      return runner(coro)\n    File \"/home/codespace/.local/lib/python3.10/site-packages/IPython/core/async_helpers.py\", line 129, in _pseudo_sync_runner\n      coro.send(None)\n    File \"/home/codespace/.local/lib/python3.10/site-packages/IPython/core/interactiveshell.py\", line 3194, in run_cell_async\n      has_raised = await self.run_ast_nodes(code_ast.body, cell_name,\n    File \"/home/codespace/.local/lib/python3.10/site-packages/IPython/core/interactiveshell.py\", line 3373, in run_ast_nodes\n      if await self.run_code(code, result, async_=asy):\n    File \"/home/codespace/.local/lib/python3.10/site-packages/IPython/core/interactiveshell.py\", line 3433, in run_code\n      exec(code_obj, self.user_global_ns, self.user_ns)\n    File \"/tmp/ipykernel_8918/4292263780.py\", line 1, in <module>\n      history = model.fit(train_generator, epochs=1, validation_data=0.2)\n    File \"/home/codespace/.python/current/lib/python3.10/site-packages/keras/utils/traceback_utils.py\", line 65, in error_handler\n      return fn(*args, **kwargs)\n    File \"/home/codespace/.python/current/lib/python3.10/site-packages/keras/engine/training.py\", line 1650, in fit\n      tmp_logs = self.train_function(iterator)\n    File \"/home/codespace/.python/current/lib/python3.10/site-packages/keras/engine/training.py\", line 1249, in train_function\n      return step_function(self, iterator)\n    File \"/home/codespace/.python/current/lib/python3.10/site-packages/keras/engine/training.py\", line 1233, in step_function\n      outputs = model.distribute_strategy.run(run_step, args=(data,))\n    File \"/home/codespace/.python/current/lib/python3.10/site-packages/keras/engine/training.py\", line 1222, in run_step\n      outputs = model.train_step(data)\n    File \"/home/codespace/.python/current/lib/python3.10/site-packages/keras/engine/training.py\", line 1024, in train_step\n      loss = self.compute_loss(x, y, y_pred, sample_weight)\n    File \"/home/codespace/.python/current/lib/python3.10/site-packages/keras/engine/training.py\", line 1082, in compute_loss\n      return self.compiled_loss(\n    File \"/home/codespace/.python/current/lib/python3.10/site-packages/keras/engine/compile_utils.py\", line 265, in __call__\n      loss_value = loss_obj(y_t, y_p, sample_weight=sw)\n    File \"/home/codespace/.python/current/lib/python3.10/site-packages/keras/losses.py\", line 152, in __call__\n      losses = call_fn(y_true, y_pred)\n    File \"/home/codespace/.python/current/lib/python3.10/site-packages/keras/losses.py\", line 284, in call\n      return ag_fn(y_true, y_pred, **self._fn_kwargs)\n    File \"/home/codespace/.python/current/lib/python3.10/site-packages/keras/losses.py\", line 2004, in categorical_crossentropy\n      return backend.categorical_crossentropy(\n    File \"/home/codespace/.python/current/lib/python3.10/site-packages/keras/backend.py\", line 5538, in categorical_crossentropy\n      return tf.nn.softmax_cross_entropy_with_logits(\nNode: 'categorical_crossentropy/softmax_cross_entropy_with_logits'\nlogits and labels must be broadcastable: logits_size=[32,4] labels_size=[32,20]\n\t [[{{node categorical_crossentropy/softmax_cross_entropy_with_logits}}]] [Op:__inference_train_function_19998]"
     ]
    }
   ],
   "source": [
    "history = model.fit(train_generator, epochs=1, validation_data=0.2)"
   ]
  }
 ],
 "metadata": {
  "kernelspec": {
   "display_name": "Python 3",
   "language": "python",
   "name": "python3"
  },
  "language_info": {
   "codemirror_mode": {
    "name": "ipython",
    "version": 3
   },
   "file_extension": ".py",
   "mimetype": "text/x-python",
   "name": "python",
   "nbconvert_exporter": "python",
   "pygments_lexer": "ipython3",
   "version": "3.10.4 (main, Nov 29 2022, 20:00:25) [GCC 9.4.0]"
  },
  "orig_nbformat": 4,
  "vscode": {
   "interpreter": {
    "hash": "3ad933181bd8a04b432d3370b9dc3b0662ad032c4dfaa4e4f1596c548f763858"
   }
  }
 },
 "nbformat": 4,
 "nbformat_minor": 2
}
